<?xml version="1.0" ?>
<robot name="arm">
  <link name="base_link">
    <inertial>
      <mass value="0.000001"/>
      <inertia ixx="0.000001" ixy="0" ixz="0" iyy="0.000001" iyz="0" izz="0.000001"/>
      <origin rpy="0 0 0" xyz="0 0 0"/>
    </inertial>
  </link>
  <link name="base">
    <inertial>
      <mass value="3.0"/>
      <inertia ixx="1.0" ixy="0" ixz="0" iyy="1.0" iyz="0" izz="1.0"/>
      <origin rpy="0 0 0" xyz="0 0 0"/>
    </inertial>
  </link>
  <link name="first_link">
    <inertial>
      <mass value="1"/>
      <inertia ixx="0.02" ixy="0" ixz="0" iyy="0.02" iyz="0" izz="0.002"/>
      <origin rpy="0 0 0" xyz="0 0 -0.5"/>
    </inertial>
    <visual>
      <origin rpy="0 0 0" xyz="0 0 -0.5"/>
      <geometry>
        <cylinder length="1.0" radius="0.05"/>
      </geometry>
    </visual>
  </link>
  <link name="second_link">
    <inertial>
      <mass value="1.0"/>
      <inertia ixx="0.02" ixy="0" ixz="0" iyy="0.02" iyz="0" izz="0.002"/>
      <origin rpy="0 0 0" xyz="0 0 -0.5"/>
    </inertial>
    <visual>
      <origin rpy="0 0 0" xyz="0 0 -0.5"/>
      <geometry>
        <cylinder length="1.0" radius="0.05"/>
      </geometry>
    </visual>
  </link>
  <link name="third_link">
    <inertial>
      <mass value="1.3"/>
      <inertia ixx="0.02" ixy="0" ixz="0" iyy="0.02" iyz="0" izz="0.002"/>
      <origin rpy="0 0 0" xyz="0 0 -0.5"/>
    </inertial>
    <visual>
      <origin rpy="0 0 0" xyz="0 0 -0.5"/>
      <geometry>
        <cylinder length="1.0" radius="0.05"/>
      </geometry>
    </visual>
  </link>
  <!-- JOINT DEFINITION -->
  <joint name="base_joint" type="fixed">
    <child link="base"/>
    <parent link="base_link"/>
    <origin rpy="0 0 0" xyz="0 0 2.5"/>
  </joint>
  <joint name="shoulder" type="revolute">
    <child link="first_link"/>
    <parent link="base"/>
    <limit effort="100.0" lower="-3.1415" upper="3.1415" velocity="5"/>
    <axis xyz="1 0 0"/>
    <origin rpy="0 0 0" xyz="0 0 0"/>
  </joint>
  <joint name="elbow" type="revolute">
    <child link="second_link"/>
    <parent link="first_link"/>
    <limit effort="100.0" lower="-3.1415" upper="3.1415" velocity="5"/>
    <axis xyz="1 0 0"/>
    <origin rpy="0 0 0" xyz="0 0 -1.0"/>
  </joint>
  <joint name="wrist" type="revolute">
    <child link="third_link"/>
    <parent link="second_link"/>
    <limit effort="100.0" lower="-3.1415" upper="3.1415" velocity="5"/>
    <axis xyz="1 0 0"/>
    <origin rpy="0 0 0" xyz="0 0 -1.0"/>
  </joint>
</robot>