<?xml version="1.0" ?>
<!-- =================================================================================== -->
<!-- |    This document was autogenerated by xacro from nao_robot_v4.xacro             | -->
<!-- |    EDITING THIS FILE BY HAND IS NOT RECOMMENDED                                 | -->
<!-- =================================================================================== -->
<robot name="arm">
  <!-- Macro for insert a link visualization -->
  <!-- Macro for insert a link collision -->
  <!-- dummy first link, directly connects with torso -->
  <link name="base_link">
    <inertial>
      <mass value="0.000001"/>
      <inertia ixx="0.000001" ixy="0" ixz="0" iyy="0.000001" iyz="0" izz="0.000001"/>
      <origin rpy="0 0 0" xyz="0 0 0"/>
    </inertial>
  </link>
  <link name="base">
    <inertial>
      <mass value="3.0"/>
      <inertia ixx="1.0" ixy="0" ixz="0" iyy="1.0" iyz="0" izz="1.0"/>
      <origin rpy="0 0 0" xyz="0 0 0"/>
    </inertial>
  </link>
  <link name="first_link">
    <inertial>
      <mass value="1"/>
      <inertia ixx="0.000001" ixy="0" ixz="0" iyy="0.000001" iyz="0" izz="0.000001"/>
      <origin rpy="0 0 0" xyz="0 0 -0.5"/>
    </inertial>
  </link>
  <link name="second_link">
    <inertial>
      <mass value="0.3"/>
      <inertia ixx="0.3" ixy="0" ixz="0" iyy="0.000001" iyz="0" izz="0.000001"/>
      <origin rpy="0 0 0" xyz="0 0 -0.5"/>
    </inertial>
  </link>
  <link name="third_link">
    <inertial>
      <mass value="0.3"/>
      <inertia ixx="0.3" ixy="0" ixz="0" iyy="0.000001" iyz="0" izz="0.000001"/>
      <origin rpy="0 0 0" xyz="0 0 -0.5"/>
    </inertial>
  </link>
  <!-- JOINT DEFINITION -->
  <!-- MACRO FOR DEFINE JOINT-->
  <!-- BASE -->
  <joint name="base_joint" type="fixed">
    <child link="base"/>
    <parent link="base_link"/>
    <origin rpy="0 0 0" xyz="0 0 0"/>
  </joint>
  <joint name="shoulder" type="prismatic">
    <child link="first_link"/>
    <parent link="base"/>
    <limit effort="100.0" lower="-2.0857" upper="2.0857" velocity="5"/>
    <axis xyz="1 0 0"/>
    <origin rpy="0 0 0" xyz="0 0 0"/>
  </joint>
  <joint name="elbow" type="revolute">
    <child link="second_link"/>
    <parent link="first_link"/>
    <limit effort="100.0" lower="-2.0857" upper="2.0857" velocity="5"/>
    <axis xyz="1 0 0"/>
    <origin rpy="0 0 0" xyz="0 0 -1.0"/>
  </joint>
    <joint name="third_joint" type="revolute">
    <child link="third_link"/>
    <parent link="second_link"/>
    <limit effort="100.0" lower="-2.0857" upper="2.0857" velocity="5"/>
    <axis xyz="1 0 0"/>
    <origin rpy="0 0 0" xyz="0 0 -1.0"/>
  </joint>


</robot>