<?xml version="1.0" ?>
<!-- Cassie V4 Model Description                                                           -->
<!-- Author: Jenna Reher (jreher@caltech.edu)                                              -->
<!-- Modified by: Nic Barbara (jreher@caltech.edu)                                         -->
<!-- This URDF is up to date with Agility Robotics specifications as of 03/20/2018.        -->
<!-- Reference: https://github.com/agilityrobotics/agility-cassie-doc/wiki/Kinematic-Model -->
<robot name ="cassie">
	<!-- Robot Link Definitions -->
	<!--     22 linkages        -->
	<link name="base_link">
		<inertial>
		  <mass value="0.000001"/>
		  <inertia ixx="0.000001" ixy="0" ixz="0" iyy="0.000001" iyz="0" izz="0.000001"/>
		  <origin rpy="0 0 0" xyz="0 0 0"/>
		</inertial>
	</link>
	<link name="lefthiproll">
		<inertial>
			<origin rpy="0 0 0" xyz="-0.01793 0.0001 -0.04428"/>
      		<mass value="1.82"/>
      		<inertia ixx="0.003431" ixy="-6.65e-07" ixz="-0.00084" iyy="0.003793" iyz="3.99e-06" izz="0.002135"/>
		</inertial>
		<visual>
			<geometry>
				<mesh filename="package://cassie_description/meshes/LeftHipRoll.stl" scale="1 1 1"/>
			</geometry>
			<material name="">
				<color rgba="1.0 0.45 0.15 1"/>
			</material>
		</visual>
	</link>
	<link name="lefthipyaw">
		<inertial>
			<origin rpy="0 0 0" xyz="0 -1e-05 -0.034277"/>
			<mass value="1.171"/>
			<inertia ixx="0.002443" ixy="-4e-08" ixz="2.462e-07" iyy="0.002803" iyz="-2.71e-08" izz="0.000842"/>
		</inertial>
		<visual>
			<geometry>
				<mesh filename="package://cassie_description/meshes/LeftHipYaw.stl" scale="1 1 1"/>
			</geometry>
			<material name="">
				<color rgba="1.0 0.45 0.15 1"/>
			</material>
		</visual>
	</link>
	<link name="lefthippitch">
		<inertial>
			<origin rpy="0 0 0" xyz="0.05946 5e-05 -0.03581"/>
			<mass value="5.52"/>
			<inertia ixx="0.010898" ixy="-0.0002669" ixz="-5.721e-05" iyy="0.029714" iyz="9.17e-06" izz="0.030257"/>
		</inertial>
		<visual>
			<geometry>
				<mesh filename="package://cassie_description/meshes/LeftHipPitch.stl" scale="1 1 1"/>
			</geometry>
			<material name="">
				<color rgba="1.0 0.45 0.15 1"/>
			</material>
		</visual>
	</link>
	<link name="leftknee">
		<inertial>
			<origin rpy="0 0 0" xyz="0.045862 0.0412393 -0.0016676"/>
			<mass value="0.9438"/>
			<inertia ixx="0.00264784327347" ixy="-0.00039744" ixz="-4.085e-05" iyy="0.00534853175914" iyz="-5.374e-05" izz="0.00764061083179"/>
		</inertial>
		<visual>
			<geometry>
				<mesh filename="package://cassie_description/meshes/left-knee.stl" scale="1 1 1"/>
			</geometry>
			<material name="">
				<color rgba="1.0 0.45 0.15 1"/>
			</material>
		</visual>
	</link>
	<link name="leftshin">
		<inertial>
			<origin rpy="0 0 0" xyz="0.18338 0.001169 0.0002123"/>
			<mass value="0.7377"/>
			<inertia ixx="0.00036" ixy="-0.00020981" ixz="2.266e-05" iyy="0.0341" iyz="-1.2e-07" izz="0.0341"/>
		</inertial>
		<visual>
			<geometry>
				<mesh filename="package://cassie_description/meshes/left-shin.stl" scale="1 1 1"/>
			</geometry>
			<material name="">
				<color rgba="1.0 0.45 0.15 1"/>
			</material>
		</visual>
	</link>
	<link name="lefttarsus">
		<inertial>
			<origin rpy="0 0 0" xyz="0.121147466 -0.02258861359 0.00325857427"/>
			<mass value="1.0267"/>
			<inertia ixx="0.00210029904934" ixy="-0.00254635550557" ixz="-4.987e-05" iyy="0.0255394864105" iyz="-4.82e-06" izz="0.0268199407448"/>
		</inertial>
		<visual>
			<geometry>
				<mesh filename="package://cassie_description/meshes/left-tarsus.stl" scale="1 1 1"/>
			</geometry>
			<material name="">
				<color rgba="1.0 0.45 0.15 1"/>
			</material>
		</visual>
	</link>
  <link name="leftheelspring">
		<inertial>
			<origin rpy="0 0 0" xyz="0.081 0.0022 0"/>
			<mass value="0.126"/>
			<inertia ixx="2.959e-05" ixy="7.15e-06" ixz="-6e-07" iyy="0.00022231" iyz="1e-07" izz="0.0002007"/>
		</inertial>
		<visual>
			<geometry>
				<mesh filename="package://cassie_description/meshes/left-heel-spring.stl" scale="1 1 1"/>
			</geometry>
			<material name="">
				<color rgba="1.0 0.45 0.15 1"/>
			</material>
		</visual>
	</link>
	<link name="leftfoot">
		<inertial>
			<origin rpy="0 0 0" xyz="0.00474 0.02748 -0.00014"/>
			<mass value="0.1498"/>
			<inertia ixx="0.00017388" ixy="0.00011814" ixz="1.36e-06" iyy="0.00016793" iyz="-4e-07" izz="0.00033261"/>
		</inertial>
		<visual>
			<geometry>
				<mesh filename="package://cassie_description/meshes/left-foot.stl" scale="1 1 1"/>
			</geometry>
			<material name="">
				<color rgba="1.0 0.45 0.15 1"/>
			</material>
		</visual>
	</link>

	<!-- Robot Joint Definitions -->
	<!--                         -->
	<joint name="LeftHipRoll" type="revolute">
		<origin rpy="0 1.570796326794897 0" xyz="-0.049 0.135 0"/>
		<axis xyz="0 0 1"/>
		<parent link="base_link"/>
		<child link="lefthiproll"/>
		<limit effort="4.5" lower="-0.261799" upper="0.392699" velocity="12.15"/>
	</joint>
	<joint name="LeftHipYaw" type="revolute">
		<origin rpy="0 -1.570796326794897 0" xyz="0.09 0 0"/>
		<axis xyz="0 0 1"/>
		<parent link="lefthiproll"/>
		<child link="lefthipyaw"/>
		<limit effort="4.5" lower="-0.392699" upper="0.392699" velocity="12.15"/>
	</joint>
	<joint name="LeftHipPitch" type="revolute">
		<origin rpy="1.57079632679 1.57079632679 0.0" xyz="0 0 0"/>
		<axis xyz="0 0 1"/>
		<parent link="lefthipyaw"/>
		<child link="lefthippitch"/>
		<limit effort="12.2" lower="-0.872665" upper="1.39626" velocity="8.5"/>
	</joint>
	<joint name="LeftKneePitch" type="revolute">
		<origin rpy="0 0 0" xyz="0.12 0 0.0045"/>
		<axis xyz="0 0 1"/>
		<parent link="lefthippitch"/>
		<child link="leftknee"/>
		<limit effort="12.2" lower="-2.86234" upper="-0.645772" velocity="8.5"/>
	</joint>
	<joint name="LeftShinPitch" type="revolute">
		<origin rpy="0 0 0" xyz="0.06068 0.04741 0"/>
		<axis xyz="0 0 1"/>
		<parent link="leftknee"/>
		<child link="leftshin"/>
		<limit effort="0" lower="-0.349066" upper="0.349066" velocity="20"/>
	</joint>
	<joint name="LeftTarsusPitch" type="revolute">
		<origin rpy="0 0 0" xyz="0.43476 0.020 0"/>
		<axis xyz="0 0 1"/>
		<parent link="leftshin"/>
		<child link="lefttarsus"/>
		<limit effort="0" lower="0.872665" upper="2.96706" velocity="20"/>
	</joint>
        <joint name="LeftAchillesSpring" type="revolute">
		<origin rpy="-0.0689428 -0.036956 2.7207121" xyz="-0.01269 -0.03059 0.00092"/>
		<axis xyz="0 0 1"/>
		<parent link="lefttarsus"/>
		<child link="leftheelspring"/>
		<limit effort="0" lower="-0.349066" upper="0.349066" velocity="20"/>
	</joint>
	<joint name="LeftFootPitch" type="revolute">
		<origin rpy="0 0 0" xyz="0.408 -0.040 0"/>
		<axis xyz="0 0 1"/>
		<parent link="lefttarsus"/>
		<child link="leftfoot"/>
		<limit effort="0.9" lower="-2.44346" upper="-0.523599" velocity="11.52"/>
	</joint>

	<!-- Robot Transmission Definitions -->
	<!--                                -->
	<transmission name="LeftHipRollTransmission">
            <joint name="LeftHipRoll"/>
            <actuator>
                    <mechanicalReduction>25</mechanicalReduction>
                    <motorInertia>6.1e-05</motorInertia>
            </actuator>
  	</transmission>
  	<transmission name="LeftHipYawTransmission">
            <joint name="LeftHipYaw"/>
            <actuator>
                    <mechanicalReduction>25</mechanicalReduction>
                    <motorInertia>6.1e-05</motorInertia>
            </actuator>
  	</transmission>
  	<transmission name="LeftHipPitchTransmission">
            <joint name="LeftHipPitch"/>
            <actuator>
                    <mechanicalReduction>16</mechanicalReduction>
                    <motorInertia>0.000365</motorInertia>
            </actuator>
  	</transmission>
  	<transmission name="LeftKneePitchTransmission">
            <joint name="LeftKneePitch"/>
            <actuator>
                    <mechanicalReduction>16</mechanicalReduction>
                    <motorInertia>0.000365</motorInertia>
            </actuator>
  	</transmission>
  	<transmission name="LeftFootPitchTransmission">
            <joint name="LeftFootPitch"/>
            <actuator>
                    <mechanicalReduction>50</mechanicalReduction>
                    <motorInertia>4.9e-06</motorInertia>
            </actuator>
  	</transmission>
</robot>
